Workbook

Sheet 713股價
A1: Column1 | B1: Column2
A2: 成交 | B2: 54.75
A3: 開盤 | B3: 54.35
A4: 最高 | B4: 54.8
A5: 最低 | B5: 54.35
A6: 均價 | B6: 54.6
A7: 成交金額(億) | B7: 10.37
A8: 昨收 | B8: 54.3
A9: 漲跌幅 | B9: 0.0083
A10: 漲跌 | B10: 0.45
A11: 總量 | B11: 18997
A12: 昨量 | B12: 23057
A13: 振幅 | B13: 0.0083

Sheet 56股價
A1: Column1 | B1: Column2
A2: 成交 | B2: 44.85
A3: 開盤 | B3: 44.7
A4: 最高 | B4: 45.2
A5: 最低 | B5: 44.29
A6: 均價 | B6: 44.83
A7: 成交金額(億) | B7: 43.22
A8: 昨收 | B8: 44.72
A9: 漲跌幅 | B9: 0.0029
A10: 漲跌 | B10: 0.13
A11: 總量 | B11: 96396
A12: 昨量 | B12: 73293
A13: 振幅 | B13: 0.0203

Sheet 927股價
A1: Column1 | B1: Column2
A2: 成交 | B2: 34.73
A3: 開盤 | B3: 34.75
A4: 最高 | B4: 35.3
A5: 最低 | B5: 33.78
A6: 均價 | B6: 34.73
A7: 成交金額(億) | B7: 11.92
A8: 昨收 | B8: 34.78
A9: 漲跌幅 | B9: 0.0014
A10: 漲跌 | B10: 0.05
A11: 總量 | B11: 34324
A12: 昨量 | B12: 24812
A13: 振幅 | B13: 0.0437

Sheet 919股價
A1: Column1 | B1: Column2
A2: 成交 | B2: 25.47
A3: 開盤 | B3: 25.52
A4: 最高 | B4: 25.72
A5: 最低 | B5: 25.31
A6: 均價 | B6: 25.52
A7: 成交金額(億) | B7: 52.86
A8: 昨收 | B8: 25.43
A9: 漲跌幅 | B9: 0.0016
A10: 漲跌 | B10: 0.04
A11: 總量 | B11: 207114
A12: 昨量 | B12: 228218
A13: 振幅 | B13: 0.0161

Sheet 878股價
A1: Column1 | B1: Column2
A2: 成交 | B2: 27.82
A3: 開盤 | B3: 27.87
A4: 最高 | B4: 28.13
A5: 最低 | B5: 27.54
A6: 均價 | B6: 27.87
A7: 成交金額(億) | B7: 31.53
A8: 昨收 | B8: 27.89
A9: 漲跌幅 | B9: 0.0025
A10: 漲跌 | B10: 0.07
A11: 總量 | B11: 113116
A12: 昨量 | B12: 82699
A13: 振幅 | B13: 0.0212

Sheet 687B股價
A1: Column1 | B1: Column2
A2: 成交 | B2: 27.78
A3: 開盤 | B3: 27.85
A4: 最高 | B4: 27.86
A5: 最低 | B5: 27.76
A6: 均價 | B6: 27.79
A7: 成交金額(億) | B7: 5.72
A8: 昨收 | B8: 27.87
A9: 漲跌幅 | B9: 0.0032
A10: 漲跌 | B10: 0.09
A11: 總量 | B11: 20588
A12: 昨量 | B12: 23642
A13: 振幅 | B13: 0.0036

Sheet 50股價
A1: Column1 | B1: Column2
A2: 成交 | B2: 97
A3: 開盤 | B3: 97.35
A4: 最高 | B4: 97.7
A5: 最低 | B5: 95.85
A6: 均價 | B6: 96.93
A7: 成交金額(億) | B7: 113.77
A8: 昨收 | B8: 97.7
A9: 漲跌幅 | B9: 0.0072
A10: 漲跌 | B10: 0.7
A11: 總量 | B11: 117375
A12: 昨量 | B12: 110211
A13: 振幅 | B13: 0.0189

Sheet 2330股價
A1: Column1 | B1: Column2
A2: 成交 | B2: 2290
A3: 開盤 | B3: 2300
A4: 最高 | B4: 2310
A5: 最低 | B5: 2265
A6: 均價 | B6: 2292
A7: 成交金額(億) | B7: 618.89
A8: 昨收 | B8: 2310
A9: 漲跌幅 | B9: 0.0087
A10: 漲跌 | B10: 20
A11: 總量 | B11: 26991
A12: 昨量 | B12: 34955
A13: 振幅 | B13: 0.0195

Sheet 年度股利總表
A2: 年度 | B2: 2023 | C2: 2024 | D2: 2025 | E2: 2026 | F2: 2027 | G2: 2028 | H2: 2029 | I2: 2030
A3: 年度股利 | B3: =SUM('00878'!F7:F9,'00919'!F7:F9,'00927'!F9:F11) -> 46180 | C3: =SUM('00878'!F14:F34,'00919'!F10:F36,'00927'!F12:F16,'0056'!F7:F34,'00713'!F7:F30,'00687B美債'!F6:F11) -> 203741 | D3: =SUM(D21+D24+D27+C30+C33+C36+B39+B42) -> 265336 | E3: =SUM(E21+E24+E27+D30+D33+D36+C39+C42) -> 0
A4: 年度投入資本 | B4: =SUM('00878'!E6:E10,'00919'!E6:E9,'00927'!E6:E11,'0056'!E6:E6,'00713'!E6:E6) -> 1272931 | C4: =SUM('00878'!E11:E35,'00919'!E10:E36,'00927'!E12:E16,'0056'!E7:E34,'00713'!E7:E30,'00687B美債'!E6:E11) -> 1809141 | D4: =SUM('00878'!E36:E75,'00919'!E37:E76,'00927'!E17:E20,'0056'!E35:E75,'00713'!E31:E70,'00687B美債'!E12:E15,'0050'!E6:E26,'2330台積電'!E6:E8) -> 548802 | E4: =SUM('00878'!E76:E111,'00919'!E77:E112,'00927'!E21:E24,'0056'!E76:E111,'00713'!E71:E107,'00687B美債'!E16:E20,'0050'!E27:E66,'2330台積電'!E9:E15) -> 0
A5: 總投入資本 | B5: =SUM('00878'!E6:E10,'00919'!E6:E9,'00927'!E6:E11,'0056'!E6:E6,'00713'!E6:E6) -> 1272931 | C5: =SUM('00878'!E6:E35,'00919'!E6:E36,'00927'!E6:E16,'0056'!E6:E34,'00713'!E6:E30,'00687B美債'!E6:E11) -> 3082072 | D5: =SUM('00878'!E6:E75,'00919'!E6:E76,'00927'!E6:E20,'0056'!E6:E75,'00713'!E6:E70,'00687B美債'!E6:E15,'0050'!E6:E26,'2330台積電'!E6:E8) -> 3630874
A20: 年度 | B20: 2023 | C20: 2024 | D20: 2025 | E20: 2026 | F20: 2027 | G20: 2028 | H20: 2029 | I20: 2030
A21: 00878股利 | B21: =SUM('00878'!F7:F9) -> 4820 | C21: =SUM('00878'!F11:F34) -> 15874 | D21: =SUM('00878'!F36:F75) -> 21576 | E21: =SUM('00878'!F76:F112) -> 0
A23: 年度 | B23: 2023 | C23: 2024 | D23: 2025 | E23: 2026 | F23: 2027 | G23: 2028 | H23: 2029 | I23: 2030
A24: 00919股利 | B24: =SUM('00919'!F6:F9) -> 21580 | C24: =SUM('00919'!F10:F36) -> 62721 | D24: =SUM('00919'!F37:F76) -> 87160 | E24: =SUM('00919'!F77:F112) -> 0
A26: 年度 | B26: 2023 | C26: 2024 | D26: 2025 | E26: 2026 | F26: 2027 | G26: 2028 | H26: 2029 | I26: 2030
A27: 00927股利 | B27: =SUM('00927'!F6:F11) -> 19780 | C27: =SUM('00927'!F12:F16) -> 91120 | D27: =SUM('00927'!F17:F20) -> 61320 | E27: =SUM('00927'!F21:F24) -> 0
A29: 年度 | B29: 2024 | C29: 2025 | D29: 2026 | E29: 2027 | F29: 2028 | G29: 2029 | H29: 2030
A30: 0056股利 | B30: =SUM('0056'!F7:F34) -> 15430 | C30: =SUM('0056'!F35:F75) -> 46046 | D30: =SUM('0056'!F76:F111) -> 0
A32: 年度 | B32: 2024 | C32: 2025 | D32: 2026 | E32: 2027 | F32: 2028 | G32: 2029 | H32: 2030
A33: 00713股利 | B33: =SUM('00713'!F7:F30) -> 2616 | C33: =SUM('00713'!F31:F70) -> 7919 | D33: =SUM('00713'!F71:F106) -> 0
A35: 年度 | B35: 2024 | C35: 2025 | D35: 2026 | E35: 2027 | F35: 2028 | G35: 2029 | H35: 2030
A36: 00687B股利 | B36: =SUM('00687B美債'!F6:F11) -> 15980 | C36: =SUM('00687B美債'!F12:F15) -> 40160 | D36: =SUM('00687B美債'!F16:F19) -> 0
A38: 年度 | B38: 2025 | C38: 2026 | D38: 2027 | E38: 2028 | F38: 2029 | G38: 2030 | H38: 2031
A39: 0050股利 | B39: =SUM('0050'!F6:F26) -> 215 | C39: =SUM('0050'!F27:F66) -> 0
A41: 年度 | B41: 2025 | C41: 2026 | D41: 2027 | E41: 2028 | F41: 2029 | G41: 2030 | H41: 2031
A42: 2330股利 | B42: =SUM('2330台積電'!F6:F8) -> 940 | C42: =SUM('2330台積電'!F9:F11) -> 0

Sheet 00878
A1: 存股統計表格 | F1: 00878(3,6,9,12)
A2: 實際成本 | B2: 帳面成本 | C2: 目前市價 | D2: 總股數 | E2: 總成本 | F2: 股利 | G2: 報酬率(含息)
A3: =(E3-F3)/D3 -> 17.380641 | B3: =E3/D3 -> 20.380216 | C3: =SUM('878股價'!B2) -> 27.82 | D3: =SUM(D6:D201) -> 14092 | E3: =SUM(E6:E201) -> 287198 | F3: =SUM(F6:F1000) -> 42270 | G3: =G4/E3 -> 0.51223003
G4: =(C3-B3)*D3+F3 -> 147111.44
A5: 交易筆數 | B5: 購買日期 | C5: 購入價格 | D5: 股數 | E5: 持有成本 | F5: 股利
A6: 1 | B6: 20230316 | C6: 16.83 | D6: 5000 | E6: 84228
A7: 2 | B7: 20230612 | F7: 1340
A8: 3 | B8: 20230911 | F8: 1740
A9: 4 | B9: 20231212 | F9: 1740
A10: 5 | B10: 20231225 | C10: 21.18 | D10: 257 | E10: 5444
A11: 6 | B11: 20240125 | C11: 21.75 | D11: 252 | E11: 5482
A12: 7 | B12: 20240226 | C12: 22.43 | D12: 242 | E12: 5429
A13: 8 | B13: 20240325 | C13: 22.56 | D13: 242 | E13: 5461
A14: 9 | B14: 20240325 | F14: 2290
A15: 10 | B15: 20240425 | C15: 21.8 | D15: 247 | E15: 5386
A16: 11 | B16: 20240527 | C16: 23.3 | D16: 235 | E16: 5477
A17: 12 | B17: 20240613 | F17: 3172
A18: 13 | B18: 20240625 | C18: 23.6 | D18: 230 | E18: 5429
A19: 14 | B19: 20240726 | C19: 23.04 | D19: 2000 | E19: 46123
A20: 15 | B20: 20240726 | C20: 23.09 | D20: 232 | E20: 5358
A21: 16 | B21: 20240815 | C21: 23.35 | D21: 97 | E21: 2266
A22: 17 | B22: 20240826 | C22: 22.93 | D22: 99 | E22: 2271
A23: 18 | B23: 20240905 | C23: 22.21 | D23: 102 | E23: 2266
A24: 19 | B24: 20240911 | F24: 4959
A25: 20 | B25: 20240916 | C25: 22.32 | D25: 102 | E25: 2278
A26: 21 | B26: 20241007 | C26: 22.73 | D26: 100 | E26: 2274
A27: 22 | B27: 20241015 | C27: 22.85 | D27: 99 | E27: 2263
A28: 23 | B28: 20241025 | C28: 23.02 | D28: 98 | E28: 2257
A29: 24 | B29: 20241105 | C29: 22.82 | D29: 99 | E29: 2260
A30: 25 | B30: 20241115 | C30: 22.78 | D30: 99 | E30: 2256
A31: 26 | B31: 20241125 | C31: 22.36 | D31: 102 | E31: 2282
A32: 27 | B32: 20241205 | C32: 22.22 | D32: 102 | E32: 2267
A33: 28 | B33: 20241212 | F33: 5453
A34: 29 | B34: 20241216 | C34: 22.26 | D34: 102 | E34: 2271
A35: 30 | B35: 20241225 | C35: 22.39 | D35: 101 | E35: 2262
A36: 31 | B36: 20250106 | C36: 22.32 | D36: 102 | E36: 2277
A37: 32 | B37: 20250115 | C37: 21.95 | D37: 103 | E37: 2262
A38: 33 | B38: 20250203 | C38: 22.1 | D38: 102 | E38: 2255
A39: 34 | B39: 20250205 | C39: 22.29 | D39: 103 | E39: 2297
A40: 35 | B40: 20250217 | C40: 22.85 | D40: 100 | E40: 2286
...

Sheet 00927
A1: 存股統計表格 | F1: 00927(2,5,8,11)
A2: 實際成本 | B2: 帳面成本 | C2: 目前市價 | D2: 總股數 | E2: 總成本 | F2: 股利 | G2: 報酬率(含息)
A3: =(E3-F3)/D3 -> 12.32275 | B3: =E3/D3 -> 15.634673 | C3: =SUM('927股價'!B2) -> 34.73 | D3: =SUM(D6:D999) -> 52000 | E3: =SUM(E6:E999) -> 813003 | F3: =SUM(F6:F999) -> 172220 | G3: =G4/E3 -> 1.4331768
G4: =(C3-B3)*D3+F3 -> 1165177
A5: 交易筆數 | B5: 購買日期 | C5: 購入價格 | D5: 股數 | E5: 持有成本 | F5: 股利
A6: 1 | B6: 20230606 | C6: 15 | D6: 10000 | E6: 150000
A7: 2 | B7: 20230606 | C7: 15.11 | D7: 5000 | E7: 75620
A8: 3 | B8: 20230607 | C8: 15.3 | D8: 30000 | E8: 459425
A9: 4 | B9: 20230811 | F9: 9890
A10: 5 | B10: 20230419 | C10: 18 | D10: 5000 | E10: 90083
A11: 6 | B11: 20231114 | F11: 9890
A12: 7 | B12: 20240221 | F12: 16190
A13: 8 | B13: 20240515 | F13: 17990
A14: 9 | B14: 20240726 | C14: 18.92 | D14: 2000 | E14: 37875
A15: 10 | B15: 20240809 | F15: 31990
A16: 11 | B16: 20241112 | F16: 24950
A17: 12 | B17: 20250221 | F17: 19230
A18: 13 | B18: 20250515 | F18: 19230
A19: 14 | B19: 20250811 | F19: 11430
A20: 15 | B20: 20251114 | F20: 11430
A21: 16
A22: 17
A23: 18
A24: 19
A25: 20
A26: 21
A27: 22
A28: 23
A29: 24
A30: 25
A31: 26
A32: 27
... A42: 37

Sheet 00919
A1: 存股統計表格 | F1: 00919(1,4,7,10)
A2: 實際成本 | B2: 帳面成本 | C2: 目前市價 | D2: 總股數 | E2: 總成本 | F2: 股利 | G2: 報酬率(含息)
A3: =(E3-F3)/D3 -> 16.184261 | B3: =E3/D3 -> 21.121516 | C3: =SUM('919股價'!B2) -> 25.47 | D3: =SUM(D6:D999) -> 34728 | E3: =SUM(E6:E999) -> 733508 | F3: =SUM(F6:F999) -> 171461 | G3: =G4/E3 -> 0.43963414
G4: =(C3-B3)*D3+F3 -> 322475.16
A5: 交易筆數 | B5: 購買日期 | C5: 購入價格 | D5: 股數 | E5: 持有成本 | F5: 股利
A6: 1 | B6: 20230607 | C6: 19.57 | D6: 20000 | E6: 391762
A7: 2 | B7: 20230714 | F7: 10790
A8: 3 | B8: 20231017 | F8: 10790
A9: 4 | B9: 20231225 | C9: 22.17 | D9: 246 | E9: 5455
A10: 5 | B10: 20240112 | F10: 10990
A11: 6 | B11: 20240125 | C11: 22.28 | D11: 245 | E11: 5460
A12: 7 | B12: 20240226 | C12: 23.66 | D12: 230 | E12: 5442
A13: 8 | B13: 20240325 | C13: 25.55 | D13: 214 | E13: 5469
A14: 9 | B14: 20240326 | C14: 24.63 | D14: 1000 | E14: 24653
A15: 10 | B15: 20240326 | C15: 24.6 | D15: 1000 | E15: 24623
A16: 11 | B16: 20240415 | F16: 13666
A17: 12 | B17: 20240425 | C17: 24.39 | D17: 223 | E17: 5440
A18: 13 | B18: 20240527 | C18: 25.73 | D18: 213 | E18: 5481
A19: 14 | B19: 20240625 | C19: 25.77 | D19: 210 | E19: 5413
A20: 15 | B20: 20240715 | F20: 16350
A21: 16 | B21: 20240726 | C21: 24.28 | D21: 220 | E21: 5343
A22: 17 | B22: 20240805 | C22: 22.65 | D22: 6000 | E22: 136026
A23: 18 | B23: 20240815 | C23: 24.48 | D23: 93 | E23: 2277
A24: 19 | B24: 20240826 | C24: 24.86 | D24: 92 | E24: 2288
A25: 20 | B25: 20240905 | C25: 24.41 | D25: 93 | E25: 2271
A26: 21 | B26: 20240916 | C26: 24.08 | D26: 94 | E26: 2265
A27: 22 | B27: 20241007 | C27: 23.48 | D27: 97 | E27: 2279
A28: 23 | B28: 20241015 | C28: 23.6 | D28: 96 | E28: 2266
A29: 24 | B29: 20241015 | F29: 21715 | N29: =N29 -> 0
A30: 25 | B30: 20241025 | C30: 23.75 | D30: 95 | E30: 2257
A31: 26 | B31: 20241105 | C31: 23.07 | D31: 98 | E31: 2262
A32: 27 | B32: 20241115 | C32: 23.3 | D32: 98 | E32: 2284
A33: 28 | B33: 20241125 | C33: 23.75 | D33: 96 | E33: 2281
A34: 29 | B34: 20241205 | C34: 23.73 | D34: 95 | E34: 2255
A35: 30 | B35: 20241216 | C35: 23.85 | D35: 95 | E35: 2267
A36: 31 | B36: 20241225 | C36: 23.48 | D36: 97 | E36: 2279
A37: 32 | B37: 20250106 | C37: 23.42 | D37: 97 | E37: 2273
A38: 33 | B38: 20250113 | F38: 22337
A39: 34 | B39: 20250115 | C39: 22.9 | D39: 99 | E39: 2268
A40: 35 | B40: 20250203 | C40: 23.14 | D40: 98 | E40: 2269
...

Sheet 0056
A1: 存股統計表格 | F1: 0056(2,5,8,11)
A2: 實際成本 | B2: 帳面成本 | C2: 目前市價 | D2: 總股數 | E2: 總成本 | F2: 股利 | G2: 報酬率(含息)
A3: =(E3-F3)/D3 -> 31.962576 | B3: =E3/D3 -> 36.554792 | C3: =SUM('56股價'!B2) -> 44.85 | D3: =SUM(D6:D1000) -> 13387 | E3: =SUM(E6:E1000) -> 489359 | F3: =SUM(F6:F1000) -> 61476 | G3: =G4/E3 -> 0.35255089
G4: =(C3-B3)*D3+F3 -> 172523.95
A5: 交易筆數 | B5: 購買日期 | C5: 購入價格 | D5: 股數 | E5: 持有成本 | F5: 股利
A6: 1 | B6: 20231225 | C6: 36.45 | D6: 150 | E6: 5469
A7: 2 | B7: 20240116 | C7: 36.31 | D7: 1000 | E7: 36344
A8: 3 | B8: 20240125 | C8: 36.36 | D8: 150 | E8: 5455
A9: 4 | B9: 20240221 | F9: 795
A10: 5 | B10: 20240226 | C10: 37.58 | D10: 155 | E10: 5450
A11: 6 | B11: 20240325 | C11: 39.82 | D11: 137 | E11: 5456
A12: 7 | B12: 20240425 | C12: 37.52 | D12: 144 | E12: 5404
A13: 8 | B13: 20240515 | F13: 1240
A14: 9 | B14: 20240527 | C14: 40.45 | D14: 136 | E14: 5502
A15: 10 | B15: 20240625 | C15: 41.2 | D15: 131 | E15: 5398
A16: 11 | B16: 20240726 | C16: 38.58 | D16: 2000 | E16: 77231
A17: 12 | B17: 20240726 | C17: 38.55 | D17: 138 | E17: 5321
A18: 13 | B18: 20240805 | C18: 35.62 | D18: 6000 | E18: 213918
A19: 14 | B19: 20240809 | F19: 2123
A20: 15 | B20: 20240815 | C20: 38.41 | D20: 59 | E20: 2267
A21: 16 | B21: 20240826 | C21: 38.9 | D21: 58 | E21: 2257
A22: 17 | B22: 20240905 | C22: 37.87 | D22: 60 | E22: 2273
A23: 18 | B23: 20240916 | C23: 37.89 | D23: 60 | E23: 2274
A24: 19 | B24: 20240925 | C24: 38.55 | D24: 59 | E24: 2276
A25: 20 | B25: 20241007 | C25: 38.57 | D25: 59 | E25: 2277
A26: 21 | B26: 20241015 | C26: 38.87 | D26: 58 | E26: 2255
A27: 22 | B27: 20241025 | C27: 37.84 | D27: 60 | E27: 2271
A28: 23 | B28: 20241105 | C28: 37.39 | D28: 60 | E28: 2245
A29: 24 | B29: 20241112 | F29: 11272
A30: 25 | B30: 20241115 | C30: 37.13 | D30: 61 | E30: 2266
A31: 26 | B31: 20241125 | C31: 37.6 | D31: 60 | E31: 2257
A32: 27 | B32: 20241205 | C32: 37.25 | D32: 61 | E32: 2273
A33: 28 | B33: 20241216 | C33: 36.97 | D33: 61 | E33: 2256
A34: 29 | B34: 20241225 | C34: 37.11 | D34: 61 | E34: 2265
A35: 30 | B35: 20250106 | C35: 37.05 | D35: 61 | E35: 2261
A36: 31 | B36: 20250115 | C36: 36.42 | D36: 62 | E36: 2259
A37: 32 | B37: 20250203 | C37: 35.46 | D37: 63 | E37: 2235
A38: 33 | B38: 20250205 | C38: 35.49 | D38: 64 | E38: 2272
A39: 34 | B39: 20250217 | C39: 36.56 | D39: 62 | E39: 2268
A40: 35 | B40: 20250220 | F40: 11858
...

Sheet 00713
A1: 存股統計表格 | F1: 00713(1,4,7,10)
A2: 實際成本 | B2: 帳面成本 | C2: 目前市價 | D2: 總股數 | E2: 總成本 | F2: 股利 | G2: 報酬率(含息)
A3: =(E3-F3)/D3 -> 51.523073 | B3: =E3/D3 -> 54.238979 | C3: =SUM('713股價'!B2) -> 54.75 | D3: =SUM(D6:D999) -> 3879 | E3: =SUM(E6:E999) -> 210393 | F3: =SUM(F6:F999) -> 10535 | G3: =G4/E3 -> 0.059494612
G4: =(C3-B3)*D3+F3 -> 12517.25
A5: 交易筆數 | B5: 購買日期 | C5: 購入價格 | D5: 股數 | E5: 持有成本 | F5: 股利
A6: 1 | B6: 20231225 | C6: 49.95 | D6: 109 | E6: 5445
A7: 2 | B7: 20240125 | C7: 49.76 | D7: 109 | E7: 5425
A8: 3 | B8: 20240226 | C8: 51.1 | D8: 106 | E8: 5418
A9: 4 | B9: 20240325 | C9: 54.55 | D9: 100 | E9: 5456
A10: 5 | B10: 20240415 | F10: 275
A11: 6 | B11: 20240425 | C11: 54.85 | D11: 98 | E11: 5376
A12: 7 | B12: 20240527 | C12: 57.7 | D12: 94 | E12: 5425
A13: 8 | B13: 20240625 | C13: 58.2 | D13: 93 | E13: 5414
A14: 9 | B14: 20240715 | F14: 914
A15: 10 | B15: 20240726 | C15: 57.3 | D15: 93 | E15: 5330
A16: 11 | B16: 20240815 | C16: 57.65 | D16: 39 | E16: 2249
A17: 12 | B17: 20240826 | C17: 58.1 | D17: 39 | E17: 2267
A18: 13 | B18: 20240905 | C18: 57.7 | D18: 39 | E18: 2251
A19: 14 | B19: 20240916 | C19: 58.3 | D19: 39 | E19: 2275
A20: 15 | B20: 20240925 | C20: 57.75 | D20: 39 | E20: 2253
A21: 16 | B21: 20241007 | C21: 57.3 | D21: 40 | E21: 2293
A22: 17 | B22: 20241015 | C22: 57 | D22: 40 | E22: 2281
A23: 18 | B23: 20241015 | F23: 1427
A24: 19 | B24: 20241025 | C24: 57.4 | D24: 39 | E24: 2240
A25: 20 | B25: 20241105 | C25: 56.4 | D25: 40 | E25: 2257
A26: 21 | B26: 20241115 | C26: 55.8 | D26: 40 | E26: 2233
A27: 22 | B27: 20241125 | C27: 55.75 | D27: 41 | E27: 2287
A28: 23 | B28: 20241205 | C28: 55.7 | D28: 40 | E28: 2229
A29: 24 | B29: 20241216 | C29: 55.8 | D29: 40 | E29: 2233
A30: 25 | B30: 20241225 | C30: 53.95 | D30: 42 | E30: 2267
A31: 26 | B31: 20250106 | C31: 53.2 | D31: 42 | E31: 2235
A32: 27 | B32: 20250113 | F32: 1834
A33: 28 | B33: 20250115 | C33: 53.1 | D33: 42 | E33: 2231
A34: 29 | B34: 20250203 | C34: 53.55 | D34: 42 | E34: 2250
A35: 30 | B35: 20250205 | C35: 53.85 | D35: 42 | E35: 2263
A36: 31 | B36: 20250225 | E36: 2254
A37: 32 | B37: 20250305 | C37: 55.2 | D37: 41 | E37: 2264
A38: 33 | B38: 20250317 | C38: 54.8 | D38: 41 | E38: 2248
A39: 34 | B39: 20250325 | C39: 53.95 | D39: 42 | E39: 2267
A40: 35 | B40: 20250331 | C40: 52.5 | D40: 1000 | E40: 52549
...

Sheet 00687B美債
A1: 存股統計表格 | F1: 00687B(1,4,7,10)
A2: 實際成本 | B2: 帳面成本 | C2: 目前市價 | D2: 總股數 | E2: 總成本 | F2: 股利 | G2: 報酬率(含息)
A3: =(E3-F3)/D3 -> 29.399233 | B3: =E3/D3 -> 31.270567 | C3: =SUM('687B股價'!B2) -> 27.78 | D3: =SUM(D6:D999) -> 30000 | E3: =SUM(E6:E999) -> 938117 | F3: =SUM(F6:F999) -> 56140 | G3: =G4/E3 -> -0.051781388
G4: =(C3-B3)*D3+F3 -> -48577
A5: 交易筆數 | B5: 購買日期 | C5: 購入價格 | D5: 股數 | E5: 持有成本 | F5: 股利
A6: 1 | B6: 20240605 | C6: 31.18 | D6: 10000 | E6: 312088
A7: 2 | B7: 20240621 | C7: 31.25 | D7: 10000 | E7: 312789
A8: 3 | B8: 20240626 | C8: 31.46 | D8: 5000 | E8: 157446
A9: 4 | B9: 20240711 | C9: 31.13 | D9: 5000 | E9: 155794
A10: 5 | B10: 20240715 | F10: 3390
A11: 6 | B11: 20241015 | F11: 12590
A12: 7 | B12: 20250113 | F12: 11390
A13: 8 | B13: 20250415 | F13: 10490
A14: 9 | B14: 20250711 | F14: 9290
A15: 10 | B15: 20251015 | F15: 8990
A16: 11
A17: 12
A18: 13
A19: 14
A20: 15
A21: 16
A22: 17
A23: 18
A24: 19
A25: 20
A26: 21
A27: 22
... A252: 247

Sheet 0050
A1: 存股統計表格 | F1: 0050
A2: 實際成本 | B2: 帳面成本 | C2: 目前市價 | D2: 總股數 | E2: 總成本 | F2: 股利 | G2: 報酬率(含息)
A3: =(E3-F3)/D3 -> 51.256625 | B3: =E3/D3 -> 51.406555 | C3: =SUM('50股價'!B2) -> 97 | D3: =SUM(D6:D999) -> 1434 | E3: =SUM(E6:E999) -> 73717 | F3: =SUM(F6:F999) -> 215 | G3: =G4/E3 -> 0.88983545
G4: =(C3-B3)*D3+F3 -> 65596
A5: 交易筆數 | B5: 購買日期 | C5: 購入價格 | D5: 股數 | E5: 持有成本 | F5: 股利
A6: 1 | B6: 20250411 | C6: 39.625 | D6: 400 | E6: 15895
A7: 2 | B7: 20250605 | C7: 45.54 | D7: 60 | E7: 2733
A8: 3 | B8: 20250625 | C8: 47.94 | D8: 57 | E8: 2734
A9: 4 | B9: 20250707 | C9: 48.55 | D9: 55 | E9: 2671
A10: 5 | B10: 20250715 | C10: 49.35 | D10: 55 | E10: 2715
A11: 6 | B11: 20250725 | C11: 51 | D11: 53 | E11: 2704
A12: 7 | B12: 20250805 | C12: 51.3 | D12: 53 | E12: 2720
A13: 8 | B13: 20250808 | F13: 215
A14: 9 | B14: 20250815 | C14: 53.05 | D14: 51 | E14: 2707
A15: 10 | B15: 20250825 | C15: 52.6 | D15: 52 | E15: 2736
A16: 11 | B16: 20250905 | C16: 52.75 | D16: 57 | E16: 3008
A17: 12 | B17: 20250915 | C17: 55.92 | D17: 59 | E17: 3301
A18: 13 | B18: 20250925 | C18: 58.17 | D18: 58 | E18: 3375
A19: 14 | B19: 20251007 | C19: 61.3 | D19: 53 | E19: 3250
A20: 15 | B20: 20251015 | C20: 61.03 | D20: 54 | E20: 3297
A21: 16 | B21: 20251027 | C21: 63.65 | D21: 53 | E21: 3373
A22: 17 | B22: 20251105 | C22: 62.63 | D22: 52 | E22: 3258
A23: 18 | B23: 20251125 | C23: 60.53 | D23: 56 | E23: 3391
A24: 19 | B24: 20251205 | C24: 62.5 | D24: 52 | E24: 3251
A25: 20 | B25: 20251215 | C25: 62.63 | D25: 52 | E25: 3258
A26: 21 | B26: 20251226 | C26: 64.22 | D26: 52 | E26: 3340
A27: 22
A28: 23
A29: 24
A30: 25
A31: 26
A32: 27
A33: 28
A34: 29
A35: 30
A36: 31
A37: 32
A38: 33
... A252: 247

Sheet 2330台積電
A1: 存股統計表格 | F1: 2330
A2: 實際成本 | B2: 帳面成本 | C2: 目前市價 | D2: 總股數 | E2: 總成本 | F2: 股利 | G2: 報酬率(含息)
A3: =(E3-F3)/D3 -> 846.39 | B3: =E3/D3 -> 855.79 | C3: =SUM('2330股價'!B2) -> 2290 | D3: =SUM(D6:D999) -> 100 | E3: =SUM(E6:E999) -> 85579 | F3: =SUM(F6:F999) -> 940 | G3: =G4/E3 -> 1.6868741
G4: =(C3-B3)*D3+F3 -> 144361
A5: 交易筆數 | B5: 購買日期 | C5: 購入價格 | D5: 股數 | E5: 持有成本 | F5: 股利
A6: 1 | B6: 20250415 | C6: 855 | D6: 100 | E6: 85579
A7: 2 | B7: 20250711 | F7: 445
A8: 3 | B8: 20251009 | F8: 495
A9: 4
A10: 5
A11: 6
A12: 7
A13: 8
A14: 9
A15: 10
A16: 11
A17: 12
A18: 13
A19: 14
A20: 15
... A252: 247

Sheet 6285股價
A1: Column1 | B1: Column2
A2: 成交 | B2: 247.5
A3: 開盤 | B3: 250
A4: 最高 | B4: 270
A5: 最低 | B5: 241.5
A6: 均價 | B6: 255.4
A7: 成交金額(億) | B7: 125.29
A8: 昨收 | B8: 256
A9: 漲跌幅 | B9: 0.0332
A10: 漲跌 | B10: 8.5
A11: 總量 | B11: 49044
A12: 昨量 | B12: 45388
A13: 振幅 | B13: 0.1113

Sheet 6285啟碁
A1: 存股統計表格 | F1: 2330
A2: 實際成本 | B2: 帳面成本 | C2: 目前市價 | D2: 總股數 | E2: 總成本 | F2: 股利 | G2: 報酬率(含息)
A3: =(E3-F3)/D3 -> 111.72 | B3: =E3/D3 -> 111.72 | C3: =SUM('6285股價'!B2) -> 247.5 | D3: =SUM(D6:D999) -> 6000 | E3: =SUM(E6:E999) -> 670320 | F3: =SUM(F6:F999) -> 0 | G3: =G4/E3 -> 1.2153598
G4: =(C3-B3)*D3+F3 -> 814680
A5: 交易筆數 | B5: 購買日期 | C5: 購入價格 | D5: 股數 | E5: 持有成本 | F5: 股利
A6: 1 | B6: 20250909 | C6: 120 | D6: 1000 | E6: 120111
A7: 2 | B7: 20250911 | C7: 118 | D7: 1000 | E7: 118109
A8: 3 | B8: 20250911 | C8: 117.5 | D8: 1000 | E8: 117609
A9: 4 | B9: 20250911 | C9: 117 | D9: 1000 | E9: 117108
A10: 5 | B10: 20251119 | C10: 99 | D10: 1000 | E10: 99092
A11: 6 | B11: 20251119 | C11: 98.2 | D11: 1000 | E11: 98291
A12: 7
A13: 8
A14: 9
A15: 10
A16: 11
A17: 12
A18: 13
A19: 14
A20: 15
A21: 16
A22: 17
A23: 18
... A252: 247
